<mujoco model="panda">
    <compiler angle="radian" autolimits="true"/>

    <default>
      <default class="panda">
        <joint armature="0.1" damping="1" axis="0 0 1" range="-2.8973 2.8973"/>
        <default class="panda/visual">
          <geom type="mesh" contype="0" conaffinity="0" group="2"/>
        </default>
        <default class="panda/collision">
          <geom type="mesh" group="3"/>
        </default>
        <site size="0.001" rgba="0.5 0.5 0.5 0.3" group="4"/>
      </default>
      <default class="hande">
        <joint damping="1" armature="0.01"/>
        <general dyntype="none" biastype="affine" ctrlrange="0 255" forcerange="-1000 1000"/>
        <default class="hande/finger">
          <joint type="slide" damping="5" armature="0.005" range="0 0.025"
            solimplimit="0.95 0.99 0.001" solreflimit="0.005 1"/>
        </default>
        <default class="hande/visual">
          <geom type="mesh" contype="0" conaffinity="0" group="2"/>
        </default>
        <default class="hande/collision">
          <geom type="mesh" group="3" solimp="0.95 0.99 0.001" solref="0.004 1"
            friction="0.7 0.2 0.001"/>
          <default class="hande/pad">
            <geom type="box" mass="0" group="3" condim="4" priority="1"
              solimp="0.95 0.99 0.001" solref="0.004 1" friction="1 0.3 0.001"/>
          </default>
        </default>
      </default>
    </default>

    <asset>
      <material name="white" rgba="1 1 1 1"/>
      <material name="off_white" rgba="0.901961 0.921569 0.929412 1"/>
      <material name="dark_grey" rgba="0.25 0.25 0.25 1"/>
      <material name="green" rgba="0 1 0 1"/>
      <material name="light_blue" rgba="0.039216 0.541176 0.780392 1"/>
      <material name="metal" rgba="0.58 0.58 0.58 1"/>
      <material name="silicone" rgba="0.1882 0.1882 0.1882 1"/>
      <material name="gray" rgba="0.4627 0.4627 0.4627 1"/>
      <material name="black" rgba="0.149 0.149 0.149 1"/>
      <material name="hande_gray" rgba="0.4 0.4 0.4 1"/>
      <material name="hande_dark_gray" rgba="0.1 0.1 0.1 1"/>

      <mesh name="link0_c" file="franka_emika_panda/meshes/link0.stl"/>
      <mesh name="link1_c" file="franka_emika_panda/meshes/link1.stl"/>
      <mesh name="link2_c" file="franka_emika_panda/meshes/link2.stl"/>
      <mesh name="link3_c" file="franka_emika_panda/meshes/link3.stl"/>
      <mesh name="link4_c" file="franka_emika_panda/meshes/link4.stl"/>
      <mesh name="link5_c0" file="franka_emika_panda/meshes/link5_collision_0.obj"/>
      <mesh name="link5_c1" file="franka_emika_panda/meshes/link5_collision_1.obj"/>
      <mesh name="link5_c2" file="franka_emika_panda/meshes/link5_collision_2.obj"/>
      <mesh name="link6_c" file="franka_emika_panda/meshes/link6.stl"/>
      <mesh name="link7_c" file="franka_emika_panda/meshes/link7.stl"/>
      <mesh file="franka_emika_panda/meshes/link0_0.obj"/>
      <mesh file="franka_emika_panda/meshes/link0_1.obj"/>
      <mesh file="franka_emika_panda/meshes/link0_2.obj"/>
      <mesh file="franka_emika_panda/meshes/link0_3.obj"/>
      <mesh file="franka_emika_panda/meshes/link0_4.obj"/>
      <mesh file="franka_emika_panda/meshes/link0_5.obj"/>
      <mesh file="franka_emika_panda/meshes/link0_7.obj"/>
      <mesh file="franka_emika_panda/meshes/link0_8.obj"/>
      <mesh file="franka_emika_panda/meshes/link0_9.obj"/>
      <mesh file="franka_emika_panda/meshes/link0_10.obj"/>
      <mesh file="franka_emika_panda/meshes/link0_11.obj"/>
      <mesh file="franka_emika_panda/meshes/link1.obj"/>
      <mesh file="franka_emika_panda/meshes/link2.obj"/>
      <mesh file="franka_emika_panda/meshes/link3_0.obj"/>
      <mesh file="franka_emika_panda/meshes/link3_1.obj"/>
      <mesh file="franka_emika_panda/meshes/link3_2.obj"/>
      <mesh file="franka_emika_panda/meshes/link3_3.obj"/>
      <mesh file="franka_emika_panda/meshes/link4_0.obj"/>
      <mesh file="franka_emika_panda/meshes/link4_1.obj"/>
      <mesh file="franka_emika_panda/meshes/link4_2.obj"/>
      <mesh file="franka_emika_panda/meshes/link4_3.obj"/>
      <mesh file="franka_emika_panda/meshes/link5_0.obj"/>
      <mesh file="franka_emika_panda/meshes/link5_1.obj"/>
      <mesh file="franka_emika_panda/meshes/link5_2.obj"/>
      <mesh file="franka_emika_panda/meshes/link6_0.obj"/>
      <mesh file="franka_emika_panda/meshes/link6_1.obj"/>
      <mesh file="franka_emika_panda/meshes/link6_2.obj"/>
      <mesh file="franka_emika_panda/meshes/link6_3.obj"/>
      <mesh file="franka_emika_panda/meshes/link6_4.obj"/>
      <mesh file="franka_emika_panda/meshes/link6_5.obj"/>
      <mesh file="franka_emika_panda/meshes/link6_6.obj"/>
      <mesh file="franka_emika_panda/meshes/link6_7.obj"/>
      <mesh file="franka_emika_panda/meshes/link6_8.obj"/>
      <mesh file="franka_emika_panda/meshes/link6_9.obj"/>
      <mesh file="franka_emika_panda/meshes/link6_10.obj"/>
      <mesh file="franka_emika_panda/meshes/link6_11.obj"/>
      <mesh file="franka_emika_panda/meshes/link6_12.obj"/>
      <mesh file="franka_emika_panda/meshes/link6_13.obj"/>
      <mesh file="franka_emika_panda/meshes/link6_14.obj"/>
      <mesh file="franka_emika_panda/meshes/link6_15.obj"/>
      <mesh file="franka_emika_panda/meshes/link6_16.obj"/>
      <mesh file="franka_emika_panda/meshes/link7_0.obj"/>
      <mesh file="franka_emika_panda/meshes/link7_1.obj"/>
      <mesh file="franka_emika_panda/meshes/link7_2.obj"/>
      <mesh file="franka_emika_panda/meshes/link7_3.obj"/>
      <mesh file="franka_emika_panda/meshes/link7_4.obj"/>
      <mesh file="franka_emika_panda/meshes/link7_5.obj"/>
      <mesh file="franka_emika_panda/meshes/link7_6.obj"/>
      <mesh file="franka_emika_panda/meshes/link7_7.obj"/>
      <mesh name="hande_body" file="robotiq_hande/meshes/hande.stl"/>
      <mesh name="hande_body_collision" file="robotiq_hande/meshes/hande-collision.stl"/>
      <mesh name="hande_coupler" file="robotiq_hande/meshes/coupler.stl"/>
      <mesh name="hande_right_finger" file="robotiq_hande/meshes/finger_1.stl"/>
      <mesh name="hande_left_finger" file="robotiq_hande/meshes/finger_2.stl"/>
      <mesh name="hande_right_finger_collision" file="robotiq_hande/meshes/finger_1-collision.stl"/>
      <mesh name="hande_left_finger_collision" file="robotiq_hande/meshes/finger_2-collision.stl"/>
    </asset>

    <worldbody>
      <body name="link0" childclass="panda">
        <inertial mass="0.629769" pos="-0.041018 -0.00014 0.049974"
          fullinertia="0.00315 0.00388 0.004285 8.2904e-7 0.00015 8.2299e-6"/>
        <geom mesh="link0_0" material="off_white" class="panda/visual"/>
        <geom mesh="link0_1" material="dark_grey" class="panda/visual"/>
        <geom mesh="link0_2" material="off_white" class="panda/visual"/>
        <geom mesh="link0_3" material="dark_grey" class="panda/visual"/>
        <geom mesh="link0_4" material="off_white" class="panda/visual"/>
        <geom mesh="link0_5" material="dark_grey" class="panda/visual"/>
        <geom mesh="link0_7" material="white" class="panda/visual"/>
        <geom mesh="link0_8" material="white" class="panda/visual"/>
        <geom mesh="link0_9" material="dark_grey" class="panda/visual"/>
        <geom mesh="link0_10" material="off_white" class="panda/visual"/>
        <geom mesh="link0_11" material="white" class="panda/visual"/>
        <geom mesh="link0_c" class="panda/collision"/>
        <body name="link1" pos="0 0 0.333">
          <inertial mass="4.970684" pos="0.003875 0.002081 -0.04762"
            fullinertia="0.70337 0.70661 0.0091170 -0.00013900 0.0067720 0.019169"/>
          <joint name="joint1"/>
          <site name="joint1"/>
          <geom material="white" mesh="link1" class="panda/visual"/>
          <geom mesh="link1_c" class="panda/collision"/>
          <body name="link2" quat="1 -1 0 0">
            <inertial mass="0.646926" pos="-0.003141 -0.02872 0.003495"
              fullinertia="0.0079620 2.8110e-2 2.5995e-2 -3.925e-3 1.0254e-2 7.04e-4"/>
            <joint name="joint2" range="-1.7628 1.7628"/>
            <site name="joint2"/>
            <geom material="white" mesh="link2" class="panda/visual"/>
            <geom mesh="link2_c" class="panda/collision"/>
            <body name="link3" pos="0 -0.316 0" quat="1 1 0 0">
              <inertial mass="3.228604" pos="2.7518e-2 3.9252e-2 -6.6502e-2"
                fullinertia="3.7242e-2 3.6155e-2 1.083e-2 -4.761e-3 -1.1396e-2 -1.2805e-2"/>
              <joint name="joint3"/>
              <site name="joint3"/>
              <geom mesh="link3_0" material="white" class="panda/visual"/>
              <geom mesh="link3_1" material="white" class="panda/visual"/>
              <geom mesh="link3_2" material="white" class="panda/visual"/>
              <geom mesh="link3_3" material="dark_grey" class="panda/visual"/>
              <geom mesh="link3_c" class="panda/collision"/>
              <body name="link4" pos="0.0825 0 0" quat="1 1 0 0">
                <inertial mass="3.587895" pos="-5.317e-2 1.04419e-1 2.7454e-2"
                  fullinertia="2.5853e-2 1.9552e-2 2.8323e-2 7.796e-3 -1.332e-3 8.641e-3"/>
                <joint name="joint4" range="-3.0718 -0.0698"/>
                <site name="joint4"/>
                <geom mesh="link4_0" material="white" class="panda/visual"/>
                <geom mesh="link4_1" material="white" class="panda/visual"/>
                <geom mesh="link4_2" material="dark_grey" class="panda/visual"/>
                <geom mesh="link4_3" material="white" class="panda/visual"/>
                <geom mesh="link4_c" class="panda/collision"/>
                <body name="link5" pos="-0.0825 0.384 0" quat="1 -1 0 0">
                  <inertial mass="1.225946" pos="-1.1953e-2 4.1065e-2 -3.8437e-2"
                    fullinertia="3.5549e-2 2.9474e-2 8.627e-3 -2.117e-3 -4.037e-3 2.29e-4"/>
                  <joint name="joint5"/>
                  <site name="joint5"/>
                  <geom mesh="link5_0" material="dark_grey" class="panda/visual"/>
                  <geom mesh="link5_1" material="white" class="panda/visual"/>
                  <geom mesh="link5_2" material="white" class="panda/visual"/>
                  <geom mesh="link5_c0" class="panda/collision"/>
                  <geom mesh="link5_c1" class="panda/collision"/>
                  <geom mesh="link5_c2" class="panda/collision"/>
                  <body name="link6" quat="1 1 0 0">
                    <inertial mass="1.666555" pos="6.0149e-2 -1.4117e-2 -1.0517e-2"
                      fullinertia="1.964e-3 4.354e-3 5.433e-3 1.09e-4 -1.158e-3 3.41e-4"/>
                    <joint name="joint6" range="-0.0175 3.7525"/>
                    <site name="joint6"/>
                    <geom mesh="link6_0" material="off_white" class="panda/visual"/>
                    <geom mesh="link6_1" material="white" class="panda/visual"/>
                    <geom mesh="link6_2" material="dark_grey" class="panda/visual"/>
                    <geom mesh="link6_3" material="white" class="panda/visual"/>
                    <geom mesh="link6_4" material="white" class="panda/visual"/>
                    <geom mesh="link6_5" material="white" class="panda/visual"/>
                    <geom mesh="link6_6" material="white" class="panda/visual"/>
                    <geom mesh="link6_7" material="light_blue" class="panda/visual"/>
                    <geom mesh="link6_8" material="light_blue" class="panda/visual"/>
                    <geom mesh="link6_9" material="dark_grey" class="panda/visual"/>
                    <geom mesh="link6_10" material="dark_grey" class="panda/visual"/>
                    <geom mesh="link6_11" material="white" class="panda/visual"/>
                    <geom mesh="link6_12" material="green" class="panda/visual"/>
                    <geom mesh="link6_13" material="white" class="panda/visual"/>
                    <geom mesh="link6_14" material="dark_grey" class="panda/visual"/>
                    <geom mesh="link6_15" material="dark_grey" class="panda/visual"/>
                    <geom mesh="link6_16" material="white" class="panda/visual"/>
                    <geom mesh="link6_c" class="panda/collision"/>
                    <body name="link7" pos="0.088 0 0" quat="1 1 0 0">
                      <inertial mass="7.35522e-01" pos="1.0517e-2 -4.252e-3 6.1597e-2"
                        fullinertia="1.2516e-2 1.0027e-2 4.815e-3 -4.28e-4 -1.196e-3 -7.41e-4"/>
                      <joint name="joint7"/>
                      <site name="joint7"/>
                      <geom mesh="link7_0" material="white" class="panda/visual"/>
                      <geom mesh="link7_1" material="dark_grey" class="panda/visual"/>
                      <geom mesh="link7_2" material="dark_grey" class="panda/visual"/>
                      <geom mesh="link7_3" material="dark_grey" class="panda/visual"/>
                      <geom mesh="link7_4" material="dark_grey" class="panda/visual"/>
                      <geom mesh="link7_5" material="dark_grey" class="panda/visual"/>
                      <geom mesh="link7_6" material="dark_grey" class="panda/visual"/>
                      <geom mesh="link7_7" material="white" class="panda/visual"/>
                      <geom mesh="link7_c" class="panda/collision"/>
                      <body name="attachment" pos="0 0 0.107" quat="0.3826834 0 0 0.9238795">
                        <camera name="handcam_depth" pos="-0.05 0 0" fovy="62" quat="0 1 -1 0"/>
                        <camera name="handcam_rgb" pos="0.06 0 0.11" fovy="55" quat="0.4662 -0.5317 0.5317 -0.4662"/>
                        <site name="attachment_site" quat="0 0 0 1"/>
                        <body name="hande" childclass="hande" quat="-1 0 0 1">
                          <geom mesh="hande_coupler" class="hande/visual" material="hande_dark_gray"/>
                          <geom mesh="hande_body" class="hande/visual" material="hande_dark_gray"/>
                          <geom mesh="hande_body_collision" class="hande/collision"/>
                          <body name="hande_left_finger" pos="0 0 0.099">
                            <inertial pos="0.02262 -0.00759 0.00738"
                              quat="0.871952 0.0369732 -0.211073 0.440205"
                              mass="0.03804" diaginertia="1.22763e-05 1.22763e-05 1.22763e-05"/>
                            <joint name="hande_left_finger_joint" axis="1 0 0" class="hande/finger"/>
                            <geom mesh="hande_left_finger" class="hande/visual" material="hande_gray"/>
                            <geom class="hande/pad" pos="-0.028 0 0.037" size="0.003 0.01 0.01"/>
                            <geom class="hande/pad" pos="-0.0306 0 0.0232" euler="0 0.52 0" size="0.003 0.01 0.006"/>
                            <geom class="hande/pad" pos="-0.033 0 0.008" size="0.003 0.01 0.012"/>
                          </body>
                          <body name="hande_right_finger" pos="0 0 0.099">
                            <inertial pos="-0.02262 0.00759 0.00738"
                              quat="0.871952 -0.0369732 0.211073 0.440205"
                              mass="0.03804" diaginertia="1.22763e-05 1.22763e-05 1.22763e-05"/>
                            <joint name="hande_right_finger_joint" axis="-1 0 0" class="hande/finger"/>
                            <geom mesh="hande_right_finger" class="hande/visual" material="hande_gray"/>
                            <geom class="hande/pad" pos="0.028 0 0.037" size="0.003 0.01 0.01"/>
                            <geom class="hande/pad" pos="0.0306 0 0.0232" euler="0 -0.52 0" size="0.003 0.01 0.006"/>
                            <geom class="hande/pad" pos="0.033 0 0.008" size="0.003 0.01 0.012"/>
                          </body>
                          <site name="tcp" pos="0 0 0.135" group="3"/>
                        </body>
                      </body>
                    </body>
                  </body>
                </body>
              </body>
            </body>
          </body>
        </body>
      </body>
    </worldbody>

    <contact>
      <exclude body1="hande" body2="hande_left_finger"/>
      <exclude body1="hande" body2="hande_right_finger"/>
    </contact>

    <tendon>
      <fixed name="split">
        <joint joint="hande_left_finger_joint" coef="0.5"/>
        <joint joint="hande_right_finger_joint" coef="0.5"/>
      </fixed>
    </tendon>

    <equality>
      <joint joint1="hande_right_finger_joint" joint2="hande_left_finger_joint"
        polycoef="0 1 0 0 0" solimp="0.95 0.99 0.001" solref="0.005 1"/>
    </equality>

    <actuator>
      <motor class="panda" name="actuator1" joint="joint1" ctrlrange="-87 87"/>
      <motor class="panda" name="actuator2" joint="joint2" ctrlrange="-87 87"/>
      <motor class="panda" name="actuator3" joint="joint3" ctrlrange="-87 87"/>
      <motor class="panda" name="actuator4" joint="joint4" ctrlrange="-87 87"/>
      <motor class="panda" name="actuator5" joint="joint5" ctrlrange="-12 12"/>
      <motor class="panda" name="actuator6" joint="joint6" ctrlrange="-12 12"/>
      <motor class="panda" name="actuator7" joint="joint7" ctrlrange="-12 12"/>
      <!-- Remap ctrlrange (0, 0.025) to (0, 255): gain = 0.025 * 1000 / 255 = 0.09804 -->
      <general class="hande" name="fingers_actuator" tendon="split" forcerange="-25 25"
        ctrlrange="0 255" gainprm="0.09804 0 0" biasprm="0 -1000 -100"/>
    </actuator>

    <sensor>
      <jointpos name="panda/joint1_pos" joint="joint1"/>
      <jointpos name="panda/joint2_pos" joint="joint2"/>
      <jointpos name="panda/joint3_pos" joint="joint3"/>
      <jointpos name="panda/joint4_pos" joint="joint4"/>
      <jointpos name="panda/joint5_pos" joint="joint5"/>
      <jointpos name="panda/joint6_pos" joint="joint6"/>
      <jointpos name="panda/joint7_pos" joint="joint7"/>

      <jointvel name="panda/joint1_vel" joint="joint1"/>
      <jointvel name="panda/joint2_vel" joint="joint2"/>
      <jointvel name="panda/joint3_vel" joint="joint3"/>
      <jointvel name="panda/joint4_vel" joint="joint4"/>
      <jointvel name="panda/joint5_vel" joint="joint5"/>
      <jointvel name="panda/joint6_vel" joint="joint6"/>
      <jointvel name="panda/joint7_vel" joint="joint7"/>

      <torque name="panda/joint1_torque" site="joint1"/>
      <torque name="panda/joint2_torque" site="joint2"/>
      <torque name="panda/joint3_torque" site="joint3"/>
      <torque name="panda/joint4_torque" site="joint4"/>
      <torque name="panda/joint5_torque" site="joint5"/>
      <torque name="panda/joint6_torque" site="joint6"/>
      <torque name="panda/joint7_torque" site="joint7"/>

      <force name="panda/wrist_force" site="attachment_site"/>

      <framepos name="hande/tcp_pos" objtype="site" objname="tcp"/>
      <framequat name="hande/tcp_quat" objtype="site" objname="tcp"/>
      <framelinvel name="hande/tcp_vel" objtype="site" objname="tcp"/>
      <frameangvel name="hande/tcp_angvel" objtype="site" objname="tcp"/>
    </sensor>
  </mujoco>
